172.31.128.83 - - [05/Jun/2025 22:01:34] "GET /processos/visualizar/d76ba2d1-4164-487a-a809-ac81628f3dbd HTTP/1.1" 500 -
Traceback (most recent call last):
  File "/home/runner/workspace/.pythonlibs/lib/python3.12/site-packages/flask/app.py", line 2552, in __call__
    return self.wsgi_app(environ, start_response)
           ^^^^^^^^^^^^^^^^^^^^^^^^^^^^^^^^^^^^^^
  File "/home/runner/workspace/.pythonlibs/lib/python3.12/site-packages/flask/app.py", line 2532, in wsgi_app
    response = self.handle_exception(e)
               ^^^^^^^^^^^^^^^^^^^^^^^^
  File "/home/runner/workspace/.pythonlibs/lib/python3.12/site-packages/flask/app.py", line 2529, in wsgi_app
    response = self.full_dispatch_request()
               ^^^^^^^^^^^^^^^^^^^^^^^^^^^^
  File "/home/runner/workspace/.pythonlibs/lib/python3.12/site-packages/flask/app.py", line 1825, in full_dispatch_request
    rv = self.handle_user_exception(e)
         ^^^^^^^^^^^^^^^^^^^^^^^^^^^^^
  File "/home/runner/workspace/.pythonlibs/lib/python3.12/site-packages/flask/app.py", line 1823, in full_dispatch_request
    rv = self.dispatch_request()
         ^^^^^^^^^^^^^^^^^^^^^^^
  File "/home/runner/workspace/.pythonlibs/lib/python3.12/site-packages/flask/app.py", line 1799, in dispatch_request
    return self.ensure_sync(self.view_functions[rule.endpoint])(**view_args)
           ^^^^^^^^^^^^^^^^^^^^^^^^^^^^^^^^^^^^^^^^^^^^^^^^^^^^^^^^^^^^^^^^^
  File "/home/runner/workspace/apps/authentication/util.py", line 57, in decorated_function
    return f(*args, **kwargs)
           ^^^^^^^^^^^^^^^^^^
  File "/home/runner/workspace/apps/processos/routes.py", line 147, in visualizar
    .first_or_404()
     ^^^^^^^^^^^^^^
  File "/home/runner/workspace/.pythonlibs/lib/python3.12/site-packages/flask_sqlalchemy/query.py", line 43, in first_or_404
    rv = self.first()
         ^^^^^^^^^^^^
  File "/home/runner/workspace/.pythonlibs/lib/python3.12/site-packages/sqlalchemy/orm/query.py", line 2743, in first
    return self.limit(1)._iter().first()  # type: ignore
           ^^^^^^^^^^^^^^^^^^^^^^^^^^^^^^^^^^^^^^^^^^^^^
  File "/home/runner/workspace/.pythonlibs/lib/python3.12/site-packages/sqlalchemy/orm/query.py", line 2842, in _iter
    result: Union[ScalarResult[_T], Result[_T]] = self.session.execute(
                                                  ^^^^^^^^^^^^^^^^^^^^^
  File "/home/runner/workspace/.pythonlibs/lib/python3.12/site-packages/sqlalchemy/orm/session.py", line 2262, in execute
    return self._execute_internal(
           ^^^^^^^^^^^^^^^^^^^^^^^
  File "/home/runner/workspace/.pythonlibs/lib/python3.12/site-packages/sqlalchemy/orm/session.py", line 2144, in _execute_internal
    result: Result[Any] = compile_state_cls.orm_execute_statement(
                          ^^^^^^^^^^^^^^^^^^^^^^^^^^^^^^^^^^^^^^^^
  File "/home/runner/workspace/.pythonlibs/lib/python3.12/site-packages/sqlalchemy/orm/context.py", line 296, in orm_execute_statement
    return cls.orm_setup_cursor_result(
           ^^^^^^^^^^^^^^^^^^^^^^^^^^^^
  File "/home/runner/workspace/.pythonlibs/lib/python3.12/site-packages/sqlalchemy/orm/context.py", line 589, in orm_setup_cursor_result
    return loading.instances(result, querycontext)
           ^^^^^^^^^^^^^^^^^^^^^^^^^^^^^^^^^^^^^^^
  File "/home/runner/workspace/.pythonlibs/lib/python3.12/site-packages/sqlalchemy/orm/loading.py", line 132, in instances
    with util.safe_reraise():
         ^^^^^^^^^^^^^^^^^^^^
  File "/home/runner/workspace/.pythonlibs/lib/python3.12/site-packages/sqlalchemy/util/langhelpers.py", line 146, in __exit__
    raise exc_value.with_traceback(exc_tb)
  File "/home/runner/workspace/.pythonlibs/lib/python3.12/site-packages/sqlalchemy/orm/loading.py", line 114, in instances
    query_entity.row_processor(context, cursor)
  File "/home/runner/workspace/.pythonlibs/lib/python3.12/site-packages/sqlalchemy/orm/context.py", line 2695, in row_processor
    _instance = loading._instance_processor(
                ^^^^^^^^^^^^^^^^^^^^^^^^^^^^
  File "/home/runner/workspace/.pythonlibs/lib/python3.12/site-packages/sqlalchemy/orm/loading.py", line 930, in _instance_processor
    prop.create_row_processor(
  File "/home/runner/workspace/.pythonlibs/lib/python3.12/site-packages/sqlalchemy/orm/interfaces.py", line 1068, in create_row_processor
    strat.create_row_processor(
  File "/home/runner/workspace/.pythonlibs/lib/python3.12/site-packages/sqlalchemy/orm/strategies.py", line 2678, in create_row_processor
    raise sa_exc.InvalidRequestError(
sqlalchemy.exc.InvalidRequestError: 'Processo.execucoes' does not support object population - eager loading cannot be applied.
172.31.128.83 - - [05/Jun/2025 22:01:35] "GET /processos/visualizar/d76ba2d1-4164-487a-a809-ac81628f3dbd?__debugger__=yes&cmd=resource&f=style.css HTTP/1.1" 200 -
172.31.128.83 - - [05/Jun/2025 22:01:35] "GET /processos/visualizar/d76ba2d1-4164-487a-a809-ac81628f3dbd?__debugger__=yes&cmd=resource&f=debugger.js HTTP/1.1" 200 -
172.31.128.83 - - [05/Jun/2025 22:01:36] "GET /processos/visualizar/d76ba2d1-4164-487a-a809-ac81628f3dbd?__debugger__=yes&cmd=resource&f=console.png HTTP/1.1" 200 -
